5:return {{["y"] = 7, ["x"] = 1, ["name"] = "slope:edge_red", ["z"] = 4, ["meta"] = {["inventory"] = {}, ["fields"] = {}}, ["param2"] = 20, ["param1"] = 14}, {["y"] = 7, ["x"] = 1, ["name"] = "slope:edge_red", ["z"] = 5, ["meta"] = {["inventory"] = {}, ["fields"] = {}}, ["param2"] = 22, ["param1"] = 14}, {["y"] = 8, ["x"] = 1, ["name"] = "slope:edge_red", ["z"] = 4, ["meta"] = {["inventory"] = {}, ["fields"] = {}}, ["param1"] = 14}, {["y"] = 8, ["x"] = 1, ["name"] = "slope:edge_red", ["z"] = 5, ["meta"] = {["inventory"] = {}, ["fields"] = {}}, ["param2"] = 2, ["param1"] = 14}, {["y"] = 4, ["x"] = 2, ["name"] = "slope:edge_red", ["z"] = 2, ["meta"] = {["inventory"] = {}, ["fields"] = {}}, ["param2"] = 20, ["param1"] = 14}, {["y"] = 4, ["x"] = 2, ["name"] = "color:red", ["z"] = 3, ["meta"] = {["inventory"] = {}, ["fields"] = {}}}, {["y"] = 4, ["x"] = 2, ["name"] = "color:red", ["z"] = 4, ["meta"] = {["inventory"] = {}, ["fields"] = {}}}, {["y"] = 4, ["x"] = 2, ["name"] = "color:red", ["z"] = 5, ["meta"] = {["inventory"] = {}, ["fields"] = {}}}, {["y"] = 4, ["x"] = 2, ["name"] = "slope:edge_red", ["z"] = 6, ["meta"] = {["inventory"] = {}, ["fields"] = {}}, ["param2"] = 22, ["param1"] = 14}, {["y"] = 5, ["x"] = 2, ["name"] = "color:red", ["z"] = 2, ["meta"] = {["inventory"] = {}, ["fields"] = {}}}, {["y"] = 5, ["x"] = 2, ["name"] = "color:red", ["z"] = 3, ["meta"] = {["inventory"] = {}, ["fields"] = {}}}, {["y"] = 5, ["x"] = 2, ["name"] = "color:red", ["z"] = 4, ["meta"] = {["inventory"] = {}, ["fields"] = {}}}, {["y"] = 5, ["x"] = 2, ["name"] = "color:red", ["z"] = 5, ["meta"] = {["inventory"] = {}, ["fields"] = {}}}, {["y"] = 5, ["x"] = 2, ["name"] = "color:red", ["z"] = 6, ["meta"] = {["inventory"] = {}, ["fields"] = {}}}, {["y"] = 6, ["x"] = 2, ["name"] = "color:red", ["z"] = 2, ["meta"] = {["inventory"] = {}, ["fields"] = {}}}, {["y"] = 6, ["x"] = 2, ["name"] = "color:red", ["z"] = 3, ["meta"] = {["inventory"] = {}, ["fields"] = {}}}, {["y"] = 6, ["x"] = 2, ["name"] = "color:red", ["z"] = 4, ["meta"] = {["inventory"] = {}, ["fields"] = {}}}, {["y"] = 6, ["x"] = 2, ["name"] = "color:red", ["z"] = 5, ["meta"] = {["inventory"] = {}, ["fields"] = {}}}, {["y"] = 6, ["x"] = 2, ["name"] = "color:red", ["z"] = 6, ["meta"] = {["inventory"] = {}, ["fields"] = {}}}, {["y"] = 7, ["x"] = 2, ["name"] = "color:red", ["z"] = 2, ["meta"] = {["inventory"] = {}, ["fields"] = {}}}, {["y"] = 7, ["x"] = 2, ["name"] = "color:red", ["z"] = 3, ["meta"] = {["inventory"] = {}, ["fields"] = {}}}, {["y"] = 7, ["x"] = 2, ["name"] = "color:red", ["z"] = 4, ["meta"] = {["inventory"] = {}, ["fields"] = {}}}, {["y"] = 7, ["x"] = 2, ["name"] = "color:red", ["z"] = 5, ["meta"] = {["inventory"] = {}, ["fields"] = {}}}, {["y"] = 7, ["x"] = 2, ["name"] = "color:red", ["z"] = 6, ["meta"] = {["inventory"] = {}, ["fields"] = {}}}, {["y"] = 8, ["x"] = 2, ["name"] = "color:red", ["z"] = 2, ["meta"] = {["inventory"] = {}, ["fields"] = {}}}, {["y"] = 8, ["x"] = 2, ["name"] = "color:red", ["z"] = 3, ["meta"] = {["inventory"] = {}, ["fields"] = {}}}, {["y"] = 8, ["x"] = 2, ["name"] = "color:red", ["z"] = 4, ["meta"] = {["inventory"] = {}, ["fields"] = {}}}, {["y"] = 8, ["x"] = 2, ["name"] = "color:red", ["z"] = 5, ["meta"] = {["inventory"] = {}, ["fields"] = {}}}, {["y"] = 8, ["x"] = 2, ["name"] = "color:red", ["z"] = 6, ["meta"] = {["inventory"] = {}, ["fields"] = {}}}, {["y"] = 9, ["x"] = 2, ["name"] = "color:red", ["z"] = 2, ["meta"] = {["inventory"] = {}, ["fields"] = {}}}, {["y"] = 9, ["x"] = 2, ["name"] = "color:red", ["z"] = 3, ["meta"] = {["inventory"] = {}, ["fields"] = {}}}, {["y"] = 9, ["x"] = 2, ["name"] = "color:red", ["z"] = 4, ["meta"] = {["inventory"] = {}, ["fields"] = {}}}, {["y"] = 9, ["x"] = 2, ["name"] = "color:red", ["z"] = 5, ["meta"] = {["inventory"] = {}, ["fields"] = {}}}, {["y"] = 9, ["x"] = 2, ["name"] = "color:red", ["z"] = 6, ["meta"] = {["inventory"] = {}, ["fields"] = {}}}, {["y"] = 10, ["x"] = 2, ["name"] = "color:red", ["z"] = 2, ["meta"] = {["inventory"] = {}, ["fields"] = {}}}, {["y"] = 10, ["x"] = 2, ["name"] = "color:red", ["z"] = 3, ["meta"] = {["inventory"] = {}, ["fields"] = {}}}, {["y"] = 10, ["x"] = 2, ["name"] = "color:red", ["z"] = 4, ["meta"] = {["inventory"] = {}, ["fields"] = {}}}, {["y"] = 10, ["x"] = 2, ["name"] = "color:red", ["z"] = 5, ["meta"] = {["inventory"] = {}, ["fields"] = {}}}, {["y"] = 10, ["x"] = 2, ["name"] = "color:red", ["z"] = 6, ["meta"] = {["inventory"] = {}, ["fields"] = {}}}, {["y"] = 11, ["x"] = 2, ["name"] = "slope:edge_red", ["z"] = 2, ["meta"] = {["inventory"] = {}, ["fields"] = {}}, ["param2"] = 1, ["param1"] = 14}, {["y"] = 11, ["x"] = 2, ["name"] = "slope:edge_red", ["z"] = 3, ["meta"] = {["inventory"] = {}, ["fields"] = {}}, ["param2"] = 1, ["param1"] = 14}, {["y"] = 11, ["x"] = 2, ["name"] = "slope:edge_red", ["z"] = 4, ["meta"] = {["inventory"] = {}, ["fields"] = {}}, ["param2"] = 1, ["param1"] = 14}, {["y"] = 11, ["x"] = 2, ["name"] = "slope:edge_red", ["z"] = 5, ["meta"] = {["inventory"] = {}, ["fields"] = {}}, ["param2"] = 1, ["param1"] = 14}, {["y"] = 11, ["x"] = 2, ["name"] = "slope:edgecorner_red", ["z"] = 6, ["meta"] = {["inventory"] = {}, ["fields"] = {}}, ["param2"] = 1, ["param1"] = 14}, {["y"] = 4, ["x"] = 3, ["name"] = "slope:edge_red", ["z"] = 2, ["meta"] = {["inventory"] = {}, ["fields"] = {}}, ["param2"] = 20, ["param1"] = 13}, {["y"] = 4, ["x"] = 3, ["name"] = "color:red", ["z"] = 3, ["meta"] = {["inventory"] = {}, ["fields"] = {}}}, {["y"] = 4, ["x"] = 3, ["name"] = "color:red", ["z"] = 4, ["meta"] = {["inventory"] = {}, ["fields"] = {}}}, {["y"] = 4, ["x"] = 3, ["name"] = "color:red", ["z"] = 5, ["meta"] = {["inventory"] = {}, ["fields"] = {}}}, {["y"] = 4, ["x"] = 3, ["name"] = "slope:edge_red", ["z"] = 6, ["meta"] = {["inventory"] = {}, ["fields"] = {}}, ["param2"] = 22, ["param1"] = 13}, {["y"] = 5, ["x"] = 3, ["name"] = "color:red", ["z"] = 2, ["meta"] = {["inventory"] = {}, ["fields"] = {}}}, {["y"] = 5, ["x"] = 3, ["name"] = "color:red", ["z"] = 6, ["meta"] = {["inventory"] = {}, ["fields"] = {}}}, {["y"] = 6, ["x"] = 3, ["name"] = "color:red", ["z"] = 2, ["meta"] = {["inventory"] = {}, ["fields"] = {}}}, {["y"] = 6, ["x"] = 3, ["name"] = "color:red", ["z"] = 6, ["meta"] = {["inventory"] = {}, ["fields"] = {}}}, {["y"] = 6, ["x"] = 3, ["name"] = "slope:edge_red", ["z"] = 7, ["meta"] = {["inventory"] = {}, ["fields"] = {}}, ["param2"] = 23, ["param1"] = 14}, {["y"] = 7, ["x"] = 3, ["name"] = "slope:edgecorner_red", ["z"] = 1, ["meta"] = {["inventory"] = {}, ["fields"] = {}}, ["param2"] = 8, ["param1"] = 14}, {["y"] = 7, ["x"] = 3, ["name"] = "color:red", ["z"] = 2, ["meta"] = {["inventory"] = {}, ["fields"] = {}}}, {["y"] = 7, ["x"] = 3, ["name"] = "color:red", ["z"] = 6, ["meta"] = {["inventory"] = {}, ["fields"] = {}}}, {["y"] = 7, ["x"] = 3, ["name"] = "color:red", ["z"] = 7, ["meta"] = {["inventory"] = {}, ["fields"] = {}}}, {["y"] = 8, ["x"] = 3, ["name"] = "slope:edge_red", ["z"] = 1, ["meta"] = {["inventory"] = {}, ["fields"] = {}}, ["param2"] = 9, ["param1"] = 14}, {["y"] = 8, ["x"] = 3, ["name"] = "color:red", ["z"] = 2, ["meta"] = {["inventory"] = {}, ["fields"] = {}}}, {["y"] = 8, ["x"] = 3, ["name"] = "slope:cylinder_orange", ["z"] = 4, ["meta"] = {["inventory"] = {}, ["fields"] = {}}, ["param2"] = 18, ["param1"] = 9}, {["y"] = 8, ["x"] = 3, ["name"] = "color:red", ["z"] = 6, ["meta"] = {["inventory"] = {}, ["fields"] = {}}}, {["y"] = 8, ["x"] = 3, ["name"] = "color:red", ["z"] = 7, ["meta"] = {["inventory"] = {}, ["fields"] = {}}}, {["y"] = 9, ["x"] = 3, ["name"] = "slope:edge_red", ["z"] = 1, ["meta"] = {["inventory"] = {}, ["fields"] = {}}, ["param2"] = 16, ["param1"] = 14}, {["y"] = 9, ["x"] = 3, ["name"] = "color:red", ["z"] = 2, ["meta"] = {["inventory"] = {}, ["fields"] = {}}}, {["y"] = 9, ["x"] = 3, ["name"] = "color:red", ["z"] = 6, ["meta"] = {["inventory"] = {}, ["fields"] = {}}}, {["y"] = 9, ["x"] = 3, ["name"] = "color:red", ["z"] = 7, ["meta"] = {["inventory"] = {}, ["fields"] = {}}}, {["y"] = 10, ["x"] = 3, ["name"] = "slope:edgecorner_red", ["z"] = 1, ["meta"] = {["inventory"] = {}, ["fields"] = {}}, ["param2"] = 9, ["param1"] = 14}, {["y"] = 10, ["x"] = 3, ["name"] = "color:red", ["z"] = 2, ["meta"] = {["inventory"] = {}, ["fields"] = {}}}, {["y"] = 10, ["x"] = 3, ["name"] = "slope:cylinder_orange", ["z"] = 4, ["meta"] = {["inventory"] = {}, ["fields"] = {}}, ["param2"] = 18, ["param1"] = 11}, {["y"] = 10, ["x"] = 3, ["name"] = "color:red", ["z"] = 6, ["meta"] = {["inventory"] = {}, ["fields"] = {}}}, {["y"] = 10, ["x"] = 3, ["name"] = "slope:edge_red", ["z"] = 7, ["meta"] = {["inventory"] = {}, ["fields"] = {}}, ["param2"] = 1, ["param1"] = 14}, {["y"] = 11, ["x"] = 3, ["name"] = "color:red", ["z"] = 2, ["meta"] = {["inventory"] = {}, ["fields"] = {}}}, {["y"] = 11, ["x"] = 3, ["name"] = "color:red", ["z"] = 3, ["meta"] = {["inventory"] = {}, ["fields"] = {}}}, {["y"] = 11, ["x"] = 3, ["name"] = "color:red", ["z"] = 4, ["meta"] = {["inventory"] = {}, ["fields"] = {}}}, {["y"] = 11, ["x"] = 3, ["name"] = "color:red", ["z"] = 5, ["meta"] = {["inventory"] = {}, ["fields"] = {}}}, {["y"] = 11, ["x"] = 3, ["name"] = "slope:edge_red", ["z"] = 6, ["meta"] = {["inventory"] = {}, ["fields"] = {}}, ["param2"] = 2, ["param1"] = 14}, {["y"] = 0, ["x"] = 4, ["name"] = "slope:cylinder_orange", ["z"] = 4, ["meta"] = {["inventory"] = {}, ["fields"] = {}}, ["param2"] = 1, ["param1"] = 11}, {["y"] = 1, ["x"] = 4, ["name"] = "slope:cylinder_orange", ["z"] = 4, ["meta"] = {["inventory"] = {}, ["fields"] = {}}, ["param2"] = 21, ["param1"] = 11}, {["y"] = 2, ["x"] = 4, ["name"] = "slope:cylinder_orange", ["z"] = 4, ["meta"] = {["inventory"] = {}, ["fields"] = {}}, ["param2"] = 21, ["param1"] = 11}, {["y"] = 3, ["x"] = 4, ["name"] = "slope:cylinder_orange", ["z"] = 4, ["meta"] = {["inventory"] = {}, ["fields"] = {}}, ["param1"] = 11}, {["y"] = 4, ["x"] = 4, ["name"] = "slope:edge_red", ["z"] = 2, ["meta"] = {["inventory"] = {}, ["fields"] = {}}, ["param2"] = 20, ["param1"] = 13}, {["y"] = 4, ["x"] = 4, ["name"] = "color:red", ["z"] = 3, ["meta"] = {["inventory"] = {}, ["fields"] = {}}}, {["y"] = 4, ["x"] = 4, ["name"] = "slope:cylinder_orange", ["z"] = 4, ["meta"] = {["inventory"] = {}, ["fields"] = {}}, ["param2"] = 3, ["param1"] = 10}, {["y"] = 4, ["x"] = 4, ["name"] = "color:red", ["z"] = 5, ["meta"] = {["inventory"] = {}, ["fields"] = {}}}, {["y"] = 4, ["x"] = 4, ["name"] = "slope:edge_red", ["z"] = 6, ["meta"] = {["inventory"] = {}, ["fields"] = {}}, ["param2"] = 22, ["param1"] = 13}, {["y"] = 5, ["x"] = 4, ["name"] = "color:red", ["z"] = 2, ["meta"] = {["inventory"] = {}, ["fields"] = {}}}, {["y"] = 5, ["x"] = 4, ["name"] = "slope:cylinder_orange", ["z"] = 4, ["meta"] = {["inventory"] = {}, ["fields"] = {}}, ["param2"] = 3, ["param1"] = 9}, {["y"] = 5, ["x"] = 4, ["name"] = "color:red", ["z"] = 6, ["meta"] = {["inventory"] = {}, ["fields"] = {}}}, {["y"] = 6, ["x"] = 4, ["name"] = "color:red", ["z"] = 2, ["meta"] = {["inventory"] = {}, ["fields"] = {}}}, {["y"] = 6, ["x"] = 4, ["name"] = "slope:cylinder_orange", ["z"] = 4, ["meta"] = {["inventory"] = {}, ["fields"] = {}}, ["param2"] = 3, ["param1"] = 8}, {["y"] = 6, ["x"] = 4, ["name"] = "color:red", ["z"] = 6, ["meta"] = {["inventory"] = {}, ["fields"] = {}}}, {["y"] = 6, ["x"] = 4, ["name"] = "color:red", ["z"] = 7, ["meta"] = {["inventory"] = {}, ["fields"] = {}}}, {["y"] = 7, ["x"] = 4, ["name"] = "slope:edge_red", ["z"] = 1, ["meta"] = {["inventory"] = {}, ["fields"] = {}}, ["param2"] = 20, ["param1"] = 14}, {["y"] = 7, ["x"] = 4, ["name"] = "color:red", ["z"] = 2, ["meta"] = {["inventory"] = {}, ["fields"] = {}}}, {["y"] = 7, ["x"] = 4, ["name"] = "slope:cylinder_orange", ["z"] = 4, ["meta"] = {["inventory"] = {}, ["fields"] = {}}, ["param2"] = 3, ["param1"] = 9}, {["y"] = 7, ["x"] = 4, ["name"] = "color:red", ["z"] = 6, ["meta"] = {["inventory"] = {}, ["fields"] = {}}}, {["y"] = 7, ["x"] = 4, ["name"] = "color:red", ["z"] = 7, ["meta"] = {["inventory"] = {}, ["fields"] = {}}}, {["y"] = 8, ["x"] = 4, ["name"] = "color:red", ["z"] = 1, ["meta"] = {["inventory"] = {}, ["fields"] = {}}}, {["y"] = 8, ["x"] = 4, ["name"] = "color:red", ["z"] = 2, ["meta"] = {["inventory"] = {}, ["fields"] = {}}}, {["y"] = 8, ["x"] = 4, ["name"] = "slope:cylinder_orange", ["z"] = 4, ["meta"] = {["inventory"] = {}, ["fields"] = {}}, ["param2"] = 3, ["param1"] = 10}, {["y"] = 8, ["x"] = 4, ["name"] = "color:red", ["z"] = 6, ["meta"] = {["inventory"] = {}, ["fields"] = {}}}, {["y"] = 8, ["x"] = 4, ["name"] = "color:red", ["z"] = 7, ["meta"] = {["inventory"] = {}, ["fields"] = {}}}, {["y"] = 9, ["x"] = 4, ["name"] = "color:red", ["z"] = 1, ["meta"] = {["inventory"] = {}, ["fields"] = {}}}, {["y"] = 9, ["x"] = 4, ["name"] = "slope:cylinder_orange", ["z"] = 2, ["meta"] = {["inventory"] = {}, ["fields"] = {}}, ["param2"] = 9, ["param1"] = 10}, {["y"] = 9, ["x"] = 4, ["name"] = "slope:cylinder_orange", ["z"] = 3, ["meta"] = {["inventory"] = {}, ["fields"] = {}}, ["param2"] = 9, ["param1"] = 11}, {["y"] = 9, ["x"] = 4, ["name"] = "slope:cylinder_orange", ["z"] = 4, ["meta"] = {["inventory"] = {}, ["fields"] = {}}, ["param2"] = 3, ["param1"] = 11}, {["y"] = 9, ["x"] = 4, ["name"] = "color:red", ["z"] = 6, ["meta"] = {["inventory"] = {}, ["fields"] = {}}}, {["y"] = 9, ["x"] = 4, ["name"] = "color:red", ["z"] = 7, ["meta"] = {["inventory"] = {}, ["fields"] = {}}}, {["y"] = 10, ["x"] = 4, ["name"] = "slope:edge_red", ["z"] = 1, ["meta"] = {["inventory"] = {}, ["fields"] = {}}, ["param1"] = 14}, {["y"] = 10, ["x"] = 4, ["name"] = "color:red", ["z"] = 2, ["meta"] = {["inventory"] = {}, ["fields"] = {}}}, {["y"] = 10, ["x"] = 4, ["name"] = "slope:cylinder_orange", ["z"] = 4, ["meta"] = {["inventory"] = {}, ["fields"] = {}}, ["param2"] = 3, ["param1"] = 12}, {["y"] = 10, ["x"] = 4, ["name"] = "color:red", ["z"] = 6, ["meta"] = {["inventory"] = {}, ["fields"] = {}}}, {["y"] = 10, ["x"] = 4, ["name"] = "color:red", ["z"] = 7, ["meta"] = {["inventory"] = {}, ["fields"] = {}}}, {["y"] = 11, ["x"] = 4, ["name"] = "color:red", ["z"] = 2, ["meta"] = {["inventory"] = {}, ["fields"] = {}}}, {["y"] = 11, ["x"] = 4, ["name"] = "color:red", ["z"] = 3, ["meta"] = {["inventory"] = {}, ["fields"] = {}}}, {["y"] = 11, ["x"] = 4, ["name"] = "color:red", ["z"] = 4, ["meta"] = {["inventory"] = {}, ["fields"] = {}}}, {["y"] = 11, ["x"] = 4, ["name"] = "color:red", ["z"] = 5, ["meta"] = {["inventory"] = {}, ["fields"] = {}}}, {["y"] = 11, ["x"] = 4, ["name"] = "slope:edge_red", ["z"] = 6, ["meta"] = {["inventory"] = {}, ["fields"] = {}}, ["param2"] = 2, ["param1"] = 14}, {["y"] = 4, ["x"] = 5, ["name"] = "slope:edge_red", ["z"] = 2, ["meta"] = {["inventory"] = {}, ["fields"] = {}}, ["param2"] = 20, ["param1"] = 13}, {["y"] = 4, ["x"] = 5, ["name"] = "color:red", ["z"] = 3, ["meta"] = {["inventory"] = {}, ["fields"] = {}}}, {["y"] = 4, ["x"] = 5, ["name"] = "color:red", ["z"] = 4, ["meta"] = {["inventory"] = {}, ["fields"] = {}}}, {["y"] = 4, ["x"] = 5, ["name"] = "color:red", ["z"] = 5, ["meta"] = {["inventory"] = {}, ["fields"] = {}}}, {["y"] = 4, ["x"] = 5, ["name"] = "slope:edge_red", ["z"] = 6, ["meta"] = {["inventory"] = {}, ["fields"] = {}}, ["param2"] = 22, ["param1"] = 13}, {["y"] = 5, ["x"] = 5, ["name"] = "color:red", ["z"] = 2, ["meta"] = {["inventory"] = {}, ["fields"] = {}}}, {["y"] = 5, ["x"] = 5, ["name"] = "color:red", ["z"] = 6, ["meta"] = {["inventory"] = {}, ["fields"] = {}}}, {["y"] = 6, ["x"] = 5, ["name"] = "color:red", ["z"] = 2, ["meta"] = {["inventory"] = {}, ["fields"] = {}}}, {["y"] = 6, ["x"] = 5, ["name"] = "color:red", ["z"] = 6, ["meta"] = {["inventory"] = {}, ["fields"] = {}}}, {["y"] = 6, ["x"] = 5, ["name"] = "slope:edge_red", ["z"] = 7, ["meta"] = {["inventory"] = {}, ["fields"] = {}}, ["param2"] = 21, ["param1"] = 14}, {["y"] = 7, ["x"] = 5, ["name"] = "slope:edgecorner_red", ["z"] = 1, ["meta"] = {["inventory"] = {}, ["fields"] = {}}, ["param2"] = 20, ["param1"] = 14}, {["y"] = 7, ["x"] = 5, ["name"] = "color:red", ["z"] = 2, ["meta"] = {["inventory"] = {}, ["fields"] = {}}}, {["y"] = 7, ["x"] = 5, ["name"] = "color:red", ["z"] = 6, ["meta"] = {["inventory"] = {}, ["fields"] = {}}}, {["y"] = 7, ["x"] = 5, ["name"] = "color:red", ["z"] = 7, ["meta"] = {["inventory"] = {}, ["fields"] = {}}}, {["y"] = 8, ["x"] = 5, ["name"] = "color:red", ["z"] = 1, ["meta"] = {["inventory"] = {}, ["fields"] = {}}}, {["y"] = 8, ["x"] = 5, ["name"] = "color:red", ["z"] = 2, ["meta"] = {["inventory"] = {}, ["fields"] = {}}}, {["y"] = 8, ["x"] = 5, ["name"] = "slope:cylinder_orange", ["z"] = 4, ["meta"] = {["inventory"] = {}, ["fields"] = {}}, ["param2"] = 12, ["param1"] = 11}, {["y"] = 8, ["x"] = 5, ["name"] = "color:red", ["z"] = 6, ["meta"] = {["inventory"] = {}, ["fields"] = {}}}, {["y"] = 8, ["x"] = 5, ["name"] = "color:red", ["z"] = 7, ["meta"] = {["inventory"] = {}, ["fields"] = {}}}, {["y"] = 9, ["x"] = 5, ["name"] = "color:red", ["z"] = 1, ["meta"] = {["inventory"] = {}, ["fields"] = {}}}, {["y"] = 9, ["x"] = 5, ["name"] = "color:red", ["z"] = 2, ["meta"] = {["inventory"] = {}, ["fields"] = {}}}, {["y"] = 9, ["x"] = 5, ["name"] = "color:red", ["z"] = 6, ["meta"] = {["inventory"] = {}, ["fields"] = {}}}, {["y"] = 9, ["x"] = 5, ["name"] = "color:red", ["z"] = 7, ["meta"] = {["inventory"] = {}, ["fields"] = {}}}, {["y"] = 10, ["x"] = 5, ["name"] = "slope:edgecorner_red", ["z"] = 1, ["meta"] = {["inventory"] = {}, ["fields"] = {}}, ["param2"] = 3, ["param1"] = 14}, {["y"] = 10, ["x"] = 5, ["name"] = "color:red", ["z"] = 2, ["meta"] = {["inventory"] = {}, ["fields"] = {}}}, {["y"] = 10, ["x"] = 5, ["name"] = "stairs:slab_red", ["z"] = 3, ["meta"] = {["inventory"] = {}, ["fields"] = {}}, ["param2"] = 21, ["param1"] = 13}, {["y"] = 10, ["x"] = 5, ["name"] = "stairs:slab_red", ["z"] = 4, ["meta"] = {["inventory"] = {}, ["fields"] = {}}, ["param2"] = 21, ["param1"] = 13}, {["y"] = 10, ["x"] = 5, ["name"] = "stairs:slab_red", ["z"] = 5, ["meta"] = {["inventory"] = {}, ["fields"] = {}}, ["param2"] = 21, ["param1"] = 13}, {["y"] = 10, ["x"] = 5, ["name"] = "color:red", ["z"] = 6, ["meta"] = {["inventory"] = {}, ["fields"] = {}}}, {["y"] = 10, ["x"] = 5, ["name"] = "slope:edge_red", ["z"] = 7, ["meta"] = {["inventory"] = {}, ["fields"] = {}}, ["param2"] = 3, ["param1"] = 14}, {["y"] = 11, ["x"] = 5, ["name"] = "slope:edge_red", ["z"] = 2, ["meta"] = {["inventory"] = {}, ["fields"] = {}}, ["param2"] = 3, ["param1"] = 14}, {["y"] = 11, ["x"] = 5, ["name"] = "slope:edge_red", ["z"] = 3, ["meta"] = {["inventory"] = {}, ["fields"] = {}}, ["param2"] = 3, ["param1"] = 14}, {["y"] = 11, ["x"] = 5, ["name"] = "slope:edge_red", ["z"] = 4, ["meta"] = {["inventory"] = {}, ["fields"] = {}}, ["param2"] = 3, ["param1"] = 14}, {["y"] = 11, ["x"] = 5, ["name"] = "slope:edge_red", ["z"] = 5, ["meta"] = {["inventory"] = {}, ["fields"] = {}}, ["param2"] = 3, ["param1"] = 14}, {["y"] = 11, ["x"] = 5, ["name"] = "slope:edgecorner_red", ["z"] = 6, ["meta"] = {["inventory"] = {}, ["fields"] = {}}, ["param2"] = 2, ["param1"] = 14}, {["y"] = 4, ["x"] = 6, ["name"] = "slope:edge_red", ["z"] = 2, ["meta"] = {["inventory"] = {}, ["fields"] = {}}, ["param2"] = 20, ["param1"] = 14}, {["y"] = 4, ["x"] = 6, ["name"] = "color:red", ["z"] = 3, ["meta"] = {["inventory"] = {}, ["fields"] = {}}}, {["y"] = 4, ["x"] = 6, ["name"] = "color:red", ["z"] = 4, ["meta"] = {["inventory"] = {}, ["fields"] = {}}}, {["y"] = 4, ["x"] = 6, ["name"] = "color:red", ["z"] = 5, ["meta"] = {["inventory"] = {}, ["fields"] = {}}}, {["y"] = 4, ["x"] = 6, ["name"] = "slope:edge_red", ["z"] = 6, ["meta"] = {["inventory"] = {}, ["fields"] = {}}, ["param2"] = 22, ["param1"] = 14}, {["y"] = 5, ["x"] = 6, ["name"] = "color:red", ["z"] = 2, ["meta"] = {["inventory"] = {}, ["fields"] = {}}}, {["y"] = 5, ["x"] = 6, ["name"] = "color:red", ["z"] = 3, ["meta"] = {["inventory"] = {}, ["fields"] = {}}}, {["y"] = 5, ["x"] = 6, ["name"] = "color:red", ["z"] = 4, ["meta"] = {["inventory"] = {}, ["fields"] = {}}}, {["y"] = 5, ["x"] = 6, ["name"] = "color:red", ["z"] = 5, ["meta"] = {["inventory"] = {}, ["fields"] = {}}}, {["y"] = 5, ["x"] = 6, ["name"] = "color:red", ["z"] = 6, ["meta"] = {["inventory"] = {}, ["fields"] = {}}}, {["y"] = 6, ["x"] = 6, ["name"] = "color:red", ["z"] = 2, ["meta"] = {["inventory"] = {}, ["fields"] = {}}}, {["y"] = 6, ["x"] = 6, ["name"] = "color:red", ["z"] = 3, ["meta"] = {["inventory"] = {}, ["fields"] = {}}}, {["y"] = 6, ["x"] = 6, ["name"] = "color:red", ["z"] = 4, ["meta"] = {["inventory"] = {}, ["fields"] = {}}}, {["y"] = 6, ["x"] = 6, ["name"] = "color:red", ["z"] = 5, ["meta"] = {["inventory"] = {}, ["fields"] = {}}}, {["y"] = 6, ["x"] = 6, ["name"] = "color:red", ["z"] = 6, ["meta"] = {["inventory"] = {}, ["fields"] = {}}}, {["y"] = 7, ["x"] = 6, ["name"] = "color:red", ["z"] = 2, ["meta"] = {["inventory"] = {}, ["fields"] = {}}}, {["y"] = 7, ["x"] = 6, ["name"] = "color:red", ["z"] = 3, ["meta"] = {["inventory"] = {}, ["fields"] = {}}}, {["y"] = 7, ["x"] = 6, ["name"] = "color:red", ["z"] = 4, ["meta"] = {["inventory"] = {}, ["fields"] = {}}}, {["y"] = 7, ["x"] = 6, ["name"] = "color:red", ["z"] = 5, ["meta"] = {["inventory"] = {}, ["fields"] = {}}}, {["y"] = 7, ["x"] = 6, ["name"] = "color:red", ["z"] = 6, ["meta"] = {["inventory"] = {}, ["fields"] = {}}}, {["y"] = 8, ["x"] = 6, ["name"] = "color:red", ["z"] = 2, ["meta"] = {["inventory"] = {}, ["fields"] = {}}}, {["y"] = 8, ["x"] = 6, ["name"] = "color:red", ["z"] = 3, ["meta"] = {["inventory"] = {}, ["fields"] = {}}}, {["y"] = 8, ["x"] = 6, ["name"] = "slope:cylinder_orange", ["z"] = 4, ["meta"] = {["inventory"] = {}, ["fields"] = {}}, ["param2"] = 12, ["param1"] = 10}, {["y"] = 8, ["x"] = 6, ["name"] = "color:red", ["z"] = 5, ["meta"] = {["inventory"] = {}, ["fields"] = {}}}, {["y"] = 8, ["x"] = 6, ["name"] = "color:red", ["z"] = 6, ["meta"] = {["inventory"] = {}, ["fields"] = {}}}, {["y"] = 9, ["x"] = 6, ["name"] = "color:red", ["z"] = 2, ["meta"] = {["inventory"] = {}, ["fields"] = {}}}, {["y"] = 9, ["x"] = 6, ["name"] = "color:red", ["z"] = 3, ["meta"] = {["inventory"] = {}, ["fields"] = {}}}, {["y"] = 9, ["x"] = 6, ["name"] = "color:red", ["z"] = 4, ["meta"] = {["inventory"] = {}, ["fields"] = {}}}, {["y"] = 9, ["x"] = 6, ["name"] = "color:red", ["z"] = 5, ["meta"] = {["inventory"] = {}, ["fields"] = {}}}, {["y"] = 9, ["x"] = 6, ["name"] = "color:red", ["z"] = 6, ["meta"] = {["inventory"] = {}, ["fields"] = {}}}, {["y"] = 10, ["x"] = 6, ["name"] = "slope:edgecorner_red", ["z"] = 2, ["meta"] = {["inventory"] = {}, ["fields"] = {}}, ["param2"] = 3, ["param1"] = 14}, {["y"] = 10, ["x"] = 6, ["name"] = "slope:edge_red", ["z"] = 3, ["meta"] = {["inventory"] = {}, ["fields"] = {}}, ["param2"] = 3, ["param1"] = 14}, {["y"] = 10, ["x"] = 6, ["name"] = "slope:edge_red", ["z"] = 4, ["meta"] = {["inventory"] = {}, ["fields"] = {}}, ["param2"] = 3, ["param1"] = 14}, {["y"] = 10, ["x"] = 6, ["name"] = "slope:edge_red", ["z"] = 5, ["meta"] = {["inventory"] = {}, ["fields"] = {}}, ["param2"] = 3, ["param1"] = 14}, {["y"] = 10, ["x"] = 6, ["name"] = "slope:edgecorner_red", ["z"] = 6, ["meta"] = {["inventory"] = {}, ["fields"] = {}}, ["param2"] = 2, ["param1"] = 14}, {["y"] = 7, ["x"] = 7, ["name"] = "slope:edgecorner_red", ["z"] = 3, ["meta"] = {["inventory"] = {}, ["fields"] = {}}, ["param2"] = 20, ["param1"] = 14}, {["y"] = 7, ["x"] = 7, ["name"] = "slope:edge_red", ["z"] = 4, ["meta"] = {["inventory"] = {}, ["fields"] = {}}, ["param2"] = 21, ["param1"] = 14}, {["y"] = 7, ["x"] = 7, ["name"] = "slope:edgecorner_red", ["z"] = 5, ["meta"] = {["inventory"] = {}, ["fields"] = {}}, ["param2"] = 21, ["param1"] = 14}, {["y"] = 8, ["x"] = 7, ["name"] = "color:red", ["z"] = 3, ["meta"] = {["inventory"] = {}, ["fields"] = {}}}, {["y"] = 8, ["x"] = 7, ["name"] = "color:red", ["z"] = 4, ["meta"] = {["inventory"] = {}, ["fields"] = {}}}, {["y"] = 8, ["x"] = 7, ["name"] = "color:red", ["z"] = 5, ["meta"] = {["inventory"] = {}, ["fields"] = {}}}, {["y"] = 9, ["x"] = 7, ["name"] = "slope:edgecorner_red", ["z"] = 3, ["meta"] = {["inventory"] = {}, ["fields"] = {}}, ["param2"] = 3, ["param1"] = 14}, {["y"] = 9, ["x"] = 7, ["name"] = "slope:edge_red", ["z"] = 4, ["meta"] = {["inventory"] = {}, ["fields"] = {}}, ["param2"] = 3, ["param1"] = 14}, {["y"] = 9, ["x"] = 7, ["name"] = "slope:edgecorner_red", ["z"] = 5, ["meta"] = {["inventory"] = {}, ["fields"] = {}}, ["param2"] = 2, ["param1"] = 14}}